Workbook

Sheet README
A1: Life Insurance Pricing & Profitability Model
A2: Personal actuarial project
A4: Purpose
A5: Build a term life insurance pricing model and understand how mortality, lapses, expenses, commission and reinsurance affect premiums and profitability.
A7: Model Structure
A8: The model starts with an individual term life policy and follows the pricing process through premium calculation, projected cash flows, reinsurance and profit testing.
A9: Then applied to a synthetic portfolio to compare profitability across different groups, review experience and test the impact of changing key assumptions.
A10: The Assumptions and Mortality sheets set out the basis used in the model. IFRS 17 GMM and Unit-Linked / VFA are included as simplified extensions of the main pricing model.
A12: Data and modelling basis
A13: Amounts are in AED. Policy and experience data are synthetic, while the product features and actuarial assumptions are illustrative and are not based on a specific insurer.
A14: Term cash flows use annual steps and year-end discounting. Profit is before tax and capital costs. Monthly premiums use a loading rather than monthly decrements.
A16: Excel conventions
... A18: Core results and sensitivities update automatically when the inputs are changed. The Checks sheet can be used to review the main validation and reconciliation checks.

Sheet Results Summary
A1: Results Summary
A2: Summary of the individual policy and synthetic portfolio results. Amounts are in AED.
A4: Technical annual premium (AED) | E4: Policy PVFP (AED) | I4: Policy NBM
A5: ='Pricing Calculator'!E8 -> 546.06076 | E5: ='Profit Testing'!B7 -> 344.85011 | I5: ='Profit Testing'!B8 -> 0.10461954
A7: Break even year | E7: Portfolio NBM | I7: Mortality A/E
A8: ='Profit Testing'!B9 -> 6 | E8: ='Portfolio Totals'!B14 -> 0.07998801 | I8: ='Experience Analysis'!B50 -> 1.2261366
A10: ="Policies priced: "&'Portfolio Totals'!B8&" Loss-making policies: "&'Portfolio Totals'!B18&" Portfolio PVFP: AED "&TEXT('Portfolio Totals'!B13,"#,##0") -> Policies priced: 169 Loss-making policies: 65 Portfolio PVFP: AED 2,56,267
A12: Projected annual policy profit | G12: Impact of key assumptions on policy PVFP
A30: Portfolio profitability by entry age
G31: Key observations
G32: ="The portfolio contains "&'Portfolio Totals'!B18&" loss-making policies. Segment results help identify where to investigate premium adequacy." -> The portfolio contains 65 loss-making policies. Segment results help identify where to investigate premium adequacy.
G35: ="Reinsurance changes policy PVFP by AED "&TEXT(Reinsurance!B11,"#,##0;(#,##0)")&". The flat ceded rate needs review alongside the reduction in retained claims." -> Reinsurance changes policy PVFP by AED 0. The flat ceded rate needs review alongside the reduction in retained claims.
G38: ="Mortality A/E is "&TEXT('Experience Analysis'!B50,"0.0%")&" based on "&'Experience Analysis'!B48&" deaths. "&'Assumption Review'!B24&"." -> Mortality A/E is 122.6% based on 26 deaths. Low credibility: retain basis and monitor.
G41: ="Gross GMM: initial CSM AED "&TEXT('IFRS 17 GMM'!B8,"#,##0")&"; loss component AED "&TEXT('IFRS 17 GMM'!B9,"#,##0")&". This differs from profitability after reinsurance." -> Gross GMM: initial CSM AED 256; loss component AED 0. This differs from profitability after reinsurance.
G44: ="The policy is most sensitive to "&Sensitivities!B38&", "&Sensitivities!B39&" and "&Sensitivities!B40&" among the assumptions tested." -> The policy is most sensitive to Expenses (±10%), Commission (pp) (±5.0pp) and Lapse rates (±20%) among the assumptions tested.
A49: Year | B49: Annual profit | C49: Discounted profit | E49: Driver | F49: Lower assumption | G49: Higher assumption | I49: Entry age | J49: Portfolio NBM
A50: =Cashflows!A4 -> 1 | B50: =Cashflows!L4 -> -712.31503 | C50: =Cashflows!N4 -> -688.22708 | E50: =Sensitivities!B38 -> Expenses (±10%) | F50: =Sensitivities!C38 -> 236.51577 | G50: =Sensitivities!D38 -> -236.51577 | I50: ='Portfolio Analysis'!A26 -> 20-29 | J50: ='Portfolio Analysis'!H26 -> 0.23642095
A51: =Cashflows!A5 -> 2 | B51: =Cashflows!L5 -> 228.46657 | C51: =Cashflows!N5 -> 213.27599 | E51: =Sensitivities!B39 -> Commission (pp) (±5.0pp) | F51: =Sensitivities!C39 -> 164.81153 | G51: =Sensitivities!D39 -> -164.81153 | I51: ='Portfolio Analysis'!A27 -> 30-39 | J51: ='Portfolio Analysis'!H27 -> 0.1195501
A52: =Cashflows!A6 -> 3 | B52: =Cashflows!L6 -> 194.83206 | C52: =Cashflows!N6 -> 175.72736 | E52: =Sensitivities!B40 -> Lapse rates (±20%) | F52: =Sensitivities!C40 -> 80.765358 | G52: =Sensitivities!D40 -> -75.304113 | I52: ='Portfolio Analysis'!A28 -> 40-49 | J52: ='Portfolio Analysis'!H28 -> 0.053280309
A53: =Cashflows!A7 -> 4 | B53: =Cashflows!L7 -> 168.01429 | C53: =Cashflows!N7 -> 146.41475 | E53: =Sensitivities!B41 -> Discount rate (±100bp) | F53: =Sensitivities!C41 -> 43.477434 | G53: =Sensitivities!D41 -> -40.291635 | I53: ='Portfolio Analysis'!A29 -> 50-59 | J53: ='Portfolio Analysis'!H29 -> -0.081048407
A54: =Cashflows!A8 -> 5 | B54: =Cashflows!L8 -> 145.95753 | C54: =Cashflows!N8 -> 122.89232 | E54: =Sensitivities!B42 -> Mortality (qx) (±10%) | F54: =Sensitivities!C42 -> 34.201242 | G54: =Sensitivities!D42 -> -34.185704 | I54: ='Portfolio Analysis'!A30 -> 60+ | J54: ='Portfolio Analysis'!H30 -> 0.16100417
A55: =Cashflows!A9 -> 6 | B55: =Cashflows!L9 -> 127.2692 | C55: =Cashflows!N9 -> 103.53358 | E55: =Sensitivities!B43 -> RI premium rate (±20%) | F55: =Sensitivities!C43 -> 0 | G55: =Sensitivities!D43 -> 0
A56: =Cashflows!A10 -> 7 | B56: =Cashflows!L10 -> 110.97831 | C56: =Cashflows!N10 -> 87.227952
A57: =Cashflows!A11 -> 8 | B57: =Cashflows!L11 -> 96.38961 | C57: =Cashflows!N11 -> 73.199383
A58: =Cashflows!A12 -> 9 | B58: =Cashflows!L12 -> 82.99289 | C58: =Cashflows!N12 -> 60.894454
A59: =Cashflows!A13 -> 10 | B59: =Cashflows!L13 -> 70.404962 | C59: =Cashflows!N13 -> 49.911402
A60: =Cashflows!A14 -> 11 | B60: =Cashflows!L14 -> 0 | C60: =Cashflows!N14 -> 0
A61: =Cashflows!A15 -> 12 | B61: =Cashflows!L15 -> 0 | C61: =Cashflows!N15 -> 0
A62: =Cashflows!A16 -> 13 | B62: =Cashflows!L16 -> 0 | C62: =Cashflows!N16 -> 0
A63: =Cashflows!A17 -> 14 | B63: =Cashflows!L17 -> 0 | C63: =Cashflows!N17 -> 0
A64: =Cashflows!A18 -> 15 | B64: =Cashflows!L18 -> 0 | C64: =Cashflows!N18 -> 0
A65: =Cashflows!A19 -> 16 | B65: =Cashflows!L19 -> 0 | C65: =Cashflows!N19 -> 0
A66: =Cashflows!A20 -> 17 | B66: =Cashflows!L20 -> 0 | C66: =Cashflows!N20 -> 0
A67: =Cashflows!A21 -> 18 | B67: =Cashflows!L21 -> 0 | C67: =Cashflows!N21 -> 0
... A89: =Cashflows!A43 -> 40 | B89: =Cashflows!L43 -> 0 | C89: =Cashflows!N43 -> 0

Sheet Pricing Calculator
A1: Term Life Pricing Calculator
A2: Change the yellow inputs to price a new policy. Amounts are in AED.
D3: Input status | E3: ='Premium Calculation'!B27 -> VALID | G3: Active scenario | H3: =Sensitivities!C16 -> Base
A5: 1. Customer & policy inputs | D5: 2. Premium | G5: 3. Policy profitability
A6: Entry age (years) | B6: 24 | D6: Charged annual premium (AED) | E6: ='Premium Calculation'!B29 -> 562.44258 | G6: PVFP (AED) | H6: ='Profit Testing'!B7 -> 344.85011
A7: Sex | B7: Male | D7: Premium per instalment (selected mode) | E7: ='Premium Calculation'!B21 -> 46.870215 | G7: New-business margin (NBM) | H7: ='Profit Testing'!B8 -> 0.10461954
A8: Smoker status | B8: Smoker | D8: Technical annual-mode premium | E8: =IFERROR('Premium Calculation'!B22/('Premium Calculation'!B23-'Premium Calculation'!B24-'Premium Calculation'!B25*'Premium Calculation'!B23),NA()) -> 546.06076 | G8: Target NBM | H8: =Assumptions!C16 -> 0.08
A9: Underwriting / risk class | B9: Preferred | D9: Technical monthly-mode instalment | E9: =IFERROR(E8*(1+Assumptions!C29)/12,NA()) -> 46.870215 | G9: Break-even year | H9: ='Profit Testing'!B9 -> 6
A10: Sum assured (AED) | B10: 100000 | D10: Premium per 1,000 sum assured | E10: ='Premium Calculation'!B20 -> 5.6244258 | G10: PV premiums (AED) | H10: ='Profit Testing'!B4 -> 3296.2306
A11: Policy term (years) | B11: 10 | D11: Pricing basis | E11: =IF(ISBLANK('Premium Calculation'!B28),"Solved to target NBM","Override in Term Life Pricing B28") -> Solved to target NBM | G11: Profitability indication | H11: =IF('Profit Testing'!B7<0,"Loss-making",IF('Profit Testing'!B8>=Assumptions!C16-0.000001,"At or above target","Below target")) -> At or above target
A12: Premium frequency | B12: Monthly | D12: Monthly premiums are based on the annual premium with a monthly payment loading applied; decrements are modelled annually.
A13: Distribution channel | B13: Bancassurance
A14: Initial commission applied | B14: ='Premium Calculation'!B32 -> 0.2
A15: Max entry age for this term | B15: =81-B11 -> 71
A16: Limits: entry age 20–(81 – term); policy term 1–40 years; sum assured > 0. Mortality rates are available up to age 80.
A18: 4. Reinsurance (surplus above retention)
A19: Sum assured | B19: =Reinsurance!B4 -> 100000
A20: Retained sum assured | B20: =Reinsurance!D4 -> 100000
A21: Ceded sum assured | B21: =Reinsurance!C4 -> 0
A22: Ceded share | B22: =IF(B19=0,0,B21/B19) -> 0
A23: PV RI recoveries | B23: =Reinsurance!B9 -> 0
A24: PV RI premiums | B24: =Reinsurance!B10 -> 0
A25: Reinsurance impact on PVFP | B25: =Reinsurance!B11 -> 0
A26: PVFP without reinsurance | B26: =Reinsurance!B12 -> 344.85011
A36: Reinsurance reduces the amount of claim risk retained by the insurer. Its overall impact can be seen by comparing the cost of reinsurance with the expected recoveries and the change in PVFP.
A50: Year | B50: Premium | C50: Net outgo | D50: Profit
A51: =Cashflows!A4 -> 1 | B51: =Cashflows!E4 -> 562.44258 | C51: =Cashflows!H4+Cashflows!I4+Cashflows!J4+Cashflows!K4 -> 1274.7576 | D51: =Cashflows!L4 -> -712.31503
A52: =Cashflows!A5 -> 2 | B52: =Cashflows!E5 -> 494.74026 | C52: =Cashflows!H5+Cashflows!I5+Cashflows!J5+Cashflows!K5 -> 266.27369 | D52: =Cashflows!L5 -> 228.46657
A53: =Cashflows!A6 -> 3 | B53: =Cashflows!E6 -> 444.07332 | C53: =Cashflows!H6+Cashflows!I6+Cashflows!J6+Cashflows!K6 -> 249.24126 | D53: =Cashflows!L6 -> 194.83206
A54: =Cashflows!A7 -> 4 | B54: =Cashflows!E7 -> 405.37099 | C54: =Cashflows!H7+Cashflows!I7+Cashflows!J7+Cashflows!K7 -> 237.3567 | D54: =Cashflows!L7 -> 168.01429
A55: =Cashflows!A8 -> 5 | B55: =Cashflows!E8 -> 375.2954 | C55: =Cashflows!H8+Cashflows!I8+Cashflows!J8+Cashflows!K8 -> 229.33788 | D55: =Cashflows!L8 -> 145.95753
A56: =Cashflows!A9 -> 6 | B56: =Cashflows!E9 -> 351.58184 | C56: =Cashflows!H9+Cashflows!I9+Cashflows!J9+Cashflows!K9 -> 224.31264 | D56: =Cashflows!L9 -> 127.2692
A57: =Cashflows!A10 -> 7 | B57: =Cashflows!E10 -> 332.6521 | C57: =Cashflows!H10+Cashflows!I10+Cashflows!J10+Cashflows!K10 -> 221.67378 | D57: =Cashflows!L10 -> 110.97831
A58: =Cashflows!A11 -> 8 | B58: =Cashflows!E11 -> 317.38 | C58: =Cashflows!H11+Cashflows!I11+Cashflows!J11+Cashflows!K11 -> 220.99039 | D58: =Cashflows!L11 -> 96.38961
A59: =Cashflows!A12 -> 9 | B59: =Cashflows!E12 -> 304.9448 | C59: =Cashflows!H12+Cashflows!I12+Cashflows!J12+Cashflows!K12 -> 221.95191 | D59: =Cashflows!L12 -> 82.99289
A60: =Cashflows!A13 -> 10 | B60: =Cashflows!E13 -> 294.737 | C60: =Cashflows!H13+Cashflows!I13+Cashflows!J13+Cashflows!K13 -> 224.33204 | D60: =Cashflows!L13 -> 70.404962
A61: =Cashflows!A14 -> 11 | B61: =Cashflows!E14 -> 0 | C61: =Cashflows!H14+Cashflows!I14+Cashflows!J14+Cashflows!K14 -> 0 | D61: =Cashflows!L14 -> 0
A62: =Cashflows!A15 -> 12 | B62: =Cashflows!E15 -> 0 | C62: =Cashflows!H15+Cashflows!I15+Cashflows!J15+Cashflows!K15 -> 0 | D62: =Cashflows!L15 -> 0
... A90: =Cashflows!A43 -> 40 | B90: =Cashflows!E43 -> 0 | C90: =Cashflows!H43+Cashflows!I43+Cashflows!J43+Cashflows!K43 -> 0 | D90: =Cashflows!L43 -> 0

Sheet Assumptions
A1: Assumptions
A3: Parameter | B3: Description | C3: Base case | D3: Unit | E3: Source / rationale
A4: Valuation_Date | B4: Reference date for portfolio calculations | C4: 2026-09-25 | D4: date | E4: Portfolio model
A5: Expense_Inflation | B5: Annual expense inflation | C5: 0.04 | D5: % | E5: Scenario assumption
A6: Discount_Rate | B6: Discount rate used for pricing and present value calculations | C6: 0.035 | D6: % | E6: Scenario assumption
A7: Investment_Return | B7: Assumed annual fund return for the unit-linked projection | C7: 0.025 | D7: % | E7: Scenario assumption
A8: Risk_Adjustment_Pct | B8: Risk adjustment as % of PV future claims and expenses | C8: 0.03 | D8: % | E8: Simplified assumption for the IFRS 17 illustration
A9: Acquisition_Expense | B9: Initial acquisition expense per policy | C9: 900 | D9: AED | E9: Portfolio assumption
A10: Maintenance_Expense | B10: Annual maintenance expense in Year 1 | C10: 220 | D10: AED p.a. | E10: Portfolio assumption
A11: Initial_Commission | B11: Default initial commission assumption | C11: 0.2 | D11: % | E11: Portfolio assumption
A12: Renewal_Commission | B12: Renewal commission as % of premium | C12: 0.05 | D12: % | E12: Portfolio assumption
A13: Base_Lapse | B13: Year 1 lapse rate | C13: 0.12 | D13: % | E13: Starting assumption for experience analysis
A14: Reinsurance_Retention | B14: Retention per life | C14: 500000 | D14: AED | E14: Portfolio assumption
A15: Reinsurance_Rate | B15: Reinsurance premium rate on ceded sum assured | C15: 0.0011 | D15: % of ceded SA | E15: Portfolio assumption
A16: Profit_Loading | B16: Target new-business margin (NBM) | C16: 0.08 | D16: % of premium | E16: Portfolio assumption
... A34: Bank_Commission | B34: Initial commission – Bancassurance channel | C34: 0.2 | D34: % | E34: Illustrative channel commission assumption
A37: Principle | B37: Explanation | E37: Classification | F37: Source
A38: Probability roll-forward | B38: Deaths first; lapses conditional on survival. | E38: General actuarial methodology
A39: Discounted profit | B39: PVFP = sum of discounted annual profits. | E39: General actuarial methodology
A40: IFRS 17 | B40: FCF, CSM and separate reinsurance-held accounting. | E40: Officially sourced context | F40: https://www.ifrs.org/issued-standards/list-of-standards/ifrs-17-insurance-contracts/

Sheet Mortality
A1: Mortality
A3: Age | B3: Female Non-smoker | C3: Female Smoker | D3: Male Non-smoker | E3: Male Smoker | F3: Preferred Factor | G3: Rated Factor
A4: 20 | B4: 0.00017186833 | C4: 0.00028358274 | D4: 0.00023252774 | E4: 0.00038367077 | F4: 0.8 | G4: 1.55
A5: 21 | B5: 0.00018618274 | C5: 0.00030720152 | D5: 0.00025189429 | E5: 0.00041562558 | F5: 0.8 | G5: 1.55
A6: 22 | B6: 0.00020168935 | C6: 0.00033278743 | D6: 0.00027287383 | E6: 0.00045024182 | F6: 0.8 | G6: 1.55
A7: 23 | B7: 0.00021848747 | C7: 0.00036050432 | D7: 0.00029560069 | E7: 0.00048774114 | F7: 0.8 | G7: 1.55
A8: 24 | B8: 0.00023668465 | C8: 0.00039052967 | D8: 0.00032022041 | E8: 0.00052836367 | F8: 0.8 | G8: 1.55
A9: 25 | B9: 0.00025639742 | C9: 0.00042305574 | D9: 0.00034689062 | E9: 0.00057236953 | F9: 0.8 | G9: 1.55
A10: 26 | B10: 0.00027775201 | C10: 0.00045829081 | D10: 0.00037578213 | E10: 0.00062004051 | F10: 0.8 | G10: 1.55
A11: 27 | B11: 0.00030088516 | C11: 0.00049646051 | D11: 0.00040707992 | E11: 0.00067168186 | F11: 0.8 | G11: 1.55
A12: 28 | B12: 0.000325945 | C12: 0.00053780925 | D12: 0.00044098441 | E12: 0.00072762428 | F12: 0.8 | G12: 1.55
A13: 29 | B13: 0.000353092 | C13: 0.0005826018 | D13: 0.00047771271 | E13: 0.00078822597 | F13: 0.8 | G13: 1.55
A14: 30 | B14: 0.0003825 | C14: 0.000631125 | D14: 0.0005175 | E14: 0.000853875 | F14: 0.8 | G14: 1.55
A15: 31 | B15: 0.0004143573 | C15: 0.00068368955 | D15: 0.00056060106 | E15: 0.00092499174 | F15: 0.8 | G15: 1.55
... A64: 80 | B64: 0.020883792 | C64: 0.034458257 | D64: 0.028254543 | E64: 0.046619995 | F64: 0.8 | G64: 1.55
A66: Illustrative mortality rates by age, sex and smoker status. Underwriting factors are shown in the Assumptions sheet.

Sheet Premium Calculation
A1: Premium Calculation
A2: Policy inputs are linked from the Pricing Calculator. An optional premium override can be entered below.
A3: Input or result | B3: Value | C3: Unit | D3: Explanation
A4: Entry age | B4: ='Pricing Calculator'!B6 -> 24 | C4: years | D4: Linked from Pricing Calculator!C6 (edit inputs there)
A5: Sex | B5: ='Pricing Calculator'!B7 -> Male | D5: Linked from Pricing Calculator!C7 (edit inputs there)
A6: Smoking status | B6: ='Pricing Calculator'!B8 -> Smoker | D6: Linked from Pricing Calculator!C8 (edit inputs there)
A7: Underwriting Class | B7: ='Pricing Calculator'!B9 -> Preferred | D7: Linked from Pricing Calculator!C9 (edit inputs there)
A8: Policy term | B8: ='Pricing Calculator'!B11 -> 10 | C8: years | D8: Linked from Pricing Calculator!C11 (edit inputs there)
A9: Sum assured | B9: ='Pricing Calculator'!B10 -> 100000 | C9: AED | D9: Linked from Pricing Calculator!C10 (edit inputs there)
A10: Premium frequency | B10: ='Pricing Calculator'!B12 -> Monthly | D10: Linked from Pricing Calculator!C12 (edit inputs there)
A11: Base qx | B11: {=_xlfn.XLOOKUP(B4,Mortality!$A$4:$A$64, _xlfn.XLOOKUP(B5&" "&B6,Mortality!$B$3:$E$3,Mortality!$B$4:$E$64))} -> 0.00052836367 | C11: % | D11: Mortality rate at entry age
A12: Underwriting-adjusted qx | B12: =B11*IF(B7="Preferred",Assumptions!C30,IF(B7="Rated",Assumptions!C31,1))*Assumptions!C21 -> 0.00042269093 | C12: % | D12: Base mortality adjusted for underwriting class
A13: Year 1 gross claims | B13: =B9*B12 -> 42.269093 | C13: AED | D13: Sum assured × adjusted mortality rate
A14: Ceded sum assured | B14: =MAX(B9-Assumptions!C14,0) -> 0 | C14: AED | D14: Surplus above retention
A15: Year 1 retained claims | B15: =B12*MIN(B9,Assumptions!C14) -> 42.269093 | C15: AED | D15: Expected claims after reinsurance recoveries
A16: Year 1 reinsurance premium | B16: =B14*Assumptions!C15 -> 0 | C16: AED | D16: Ceded sum assured × reinsurance premium rate
A17: Year 1 expenses | B17: =(Assumptions!C9+Assumptions!C10)*Assumptions!C23 -> 1120 | C17: AED | D17: Acquisition and maintenance expenses
A18: Year 1 commission | B18: =B29*(B32+Assumptions!C24) -> 112.48852 | C18: AED | D18: Charged premium × initial commission rate
A19: Technical annual premium | B19: =IF(B27="VALID",B22/(B23-B24-Assumptions!C16*B23)*IF(B10="Monthly",1+Assumptions!C29,1),NA()) -> 562.44258 | C19: AED | D19: Premium required to meet the target NBM
A20: Premium per 1,000 sum assured | B20: =B29/B9*1000 -> 5.6244258 | C20: AED | D20: Annual premium expressed per AED 1,000 of sum assured
A21: Premium per instalment | B21: =B29/IF(B10="Monthly",12,1) -> 46.870215 | C21: AED | D21: Premium payable for the selected payment frequency
A22: PV claims and expenses | B22: =SUM(Cashflows!Q4:Q43) -> 2705.0555 | C22: AED | D22: Present value of retained claims, expenses and reinsurance premiums
A23: PV unit premium annuity | B23: =SUM(Cashflows!O4:O43) -> 5.8605636 | C23: factor | D23: Present value factor for future premiums
A24: PV commission coefficient | B24: =SUM(Cashflows!P4:P43) -> 0.43795572 | C24: factor | D24: Present value factor for future commission payments
A25: Target NBM | B25: =Assumptions!C16 -> 0.08 | C25: % | D25: PVFP / PV premiums
A26: Premium equation residual | B26: =B19/IF(B10="Monthly",1+Assumptions!C29,1)*(B23-B24-B25*B23)-B22 -> 0 | C26: AED | D26: Should be zero when the premium is solved
A27: Input status | B27: =IFERROR(IF(AND(COUNT(B4,B8,B9)=3,COUNT(Assumptions!C5:C34)=30,Assumptions!C9>=0,Assumptions!C10>=0,Assumptions!C5>-1,Assumptions!C27>=0,Assumptions!C27<=1,Assumptions!C28>=0,Assumptions!C28<=1,Assumptions!C29>=0,Assumptions!C30>0,Assumptions!C31>0,B23-B24-Assumptions!C16*B23>0,B4=INT(B4),B4>=20,B8=INT(B8),B8>=1,B8<=40,B4+B8-1<=80,B9>0,OR(B5="Male",B5="Female"),OR(B6="Smoker",B6="Non-smoker"),OR(B7="Standard",B7="Preferred",B7="Rated"),OR(B10="Annual",B10="Monthly"),OR(B31="Direct",B31="Broker",B31="Bancassurance",B31="Generic"),Assumptions!C6+Assumptions!C25>-1,Assumptions!C13>=0,Assumptions!C13<=1,Assumptions!C14>=0,Assumptions!C15>=0,Assumptions!C21>=0,Assumptions!C22>=0,Assumptions!C23>=0,B32+Assumptions!C24>=0,B32+Assumptions!C24<1,Assumptions!C12+Assumptions!C24>=0,Assumptions!C12+Assumptions!C24<1,Assumptions!C16>=0,Assumptions!C16<1,OR(ISBLANK(B28),AND(ISNUMBER(B28),B28>=0))),"VALID","INVALID INPUT"),"INVALID INPUT") -> VALID | D27: Check the yellow input cells if the status is invalid
A28: Annual premium override | C28: AED | D28: Leave blank to use the technical premium; enter a value to test a different premium.
A29: Charged annual premium | B29: =IF(ISBLANK(B28),B19,B28) -> 562.44258 | C29: AED | D29: Premium used for profit testing, sensitivities and comparisons
A31: Distribution channel | B31: ='Pricing Calculator'!B13 -> Bancassurance | D31: Selected distribution channel from the Pricing Calculator
A32: Initial commission rate | B32: =IF(B31="Direct",Assumptions!C32,IF(B31="Broker",Assumptions!C33,IF(B31="Bancassurance",Assumptions!C34,Assumptions!C11))) -> 0.2 | C32: % | D32: Commission rate based on the selected distribution channel

Sheet Cashflows
A1: Projected Cash Flows
A2: Annual projection of premiums, claims, expenses, reinsurance and profit for the selected policy.
A3: Year | B3: Opening in-force | C3: Annual qx | D3: Lapse rate | E3: Premium | F3: Gross claims | G3: Ceded claims | H3: Retained claims | I3: Expenses | J3: Commission | K3: Reinsurance premium | L3: Annual profit | M3: Discount factor | N3: PV profit | O3: PV premium factor | P3: PV commission factor | Q3: PV claims & expenses | R3: Closing in-force | S3: Deaths | T3: Lapses | U3: Roll-forward check
A4: 1 | B4: =IF(A4<='Premium Calculation'!$B$8,1,0) -> 1 | C4: {=IF(B4=0,0,_xlfn.XLOOKUP('Premium Calculation'!$B$4+A4-1,Mortality!$A$4:$A$64,_xlfn.XLOOKUP('Premium Calculation'!$B$5&" "&'Premium Calculation'!$B$6,Mortality!$B$3:$E$3,Mortality!$B$4:$E$64))*IF('Premium Calculation'!$B$7="Preferred",Assumptions!$C$30,IF('Premium Calculation'!$B$7="Rated",Assumptions!$C$31,1))*Assumptions!$C$21)} -> 0.00042269093 | D4: =IF(B4=0,0,MIN(1,MAX(Assumptions!$C$27,Assumptions!$C$13*Assumptions!$C$28^(A4-1))*Assumptions!$C$22)) -> 0.12 | E4: =B4*'Premium Calculation'!$B$29 -> 562.44258 | F4: =B4*C4*'Premium Calculation'!$B$9 -> 42.269093 | G4: =B4*C4*'Premium Calculation'!$B$14 -> 0 | H4: =F4-G4 -> 42.269093 | I4: =B4*(Assumptions!$C$10*(1+Assumptions!$C$5)^(A4-1)+IF(A4=1,Assumptions!$C$9,0))*Assumptions!$C$23 -> 1120 | J4: =E4*(IF(A4=1,'Premium Calculation'!$B$32,Assumptions!$C$12)+Assumptions!$C$24) -> 112.48852 | K4: =B4*'Premium Calculation'!$B$14*Assumptions!$C$15 -> 0 | L4: =E4-H4-I4-J4-K4 -> -712.31503 | M4: =(1+Assumptions!$C$6+Assumptions!$C$25)^(-A4) -> 0.96618357 | N4: =L4*M4 -> -688.22708 | O4: =B4*M4 -> 0.96618357 | P4: =O4*(IF(A4=1,'Premium Calculation'!$B$32,Assumptions!$C$12)+Assumptions!$C$24) -> 0.19323671 | Q4: =(H4+I4+K4)*M4 -> 1122.9653 | R4: =B4-S4-T4 -> 0.87962803 | S4: =B4*C4 -> 0.00042269093 | T4: =(B4-S4)*D4 -> 0.11994928 | U4: =B4-R4-S4-T4 -> 0
A5: 2 | B5: =IF(A5<='Premium Calculation'!$B$8,R4,0) -> 0.87962803 | C5: {=IF(B5=0,0,_xlfn.XLOOKUP('Premium Calculation'!$B$4+A5-1,Mortality!$A$4:$A$64,_xlfn.XLOOKUP('Premium Calculation'!$B$5&" "&'Premium Calculation'!$B$6,Mortality!$B$3:$E$3,Mortality!$B$4:$E$64))*IF('Premium Calculation'!$B$7="Preferred",Assumptions!$C$30,IF('Premium Calculation'!$B$7="Rated",Assumptions!$C$31,1))*Assumptions!$C$21)} -> 0.00045789562 | D5: =IF(B5=0,0,MIN(1,MAX(Assumptions!$C$27,Assumptions!$C$13*Assumptions!$C$28^(A5-1))*Assumptions!$C$22)) -> 0.102 | E5: =B5*'Premium Calculation'!$B$29 -> 494.74026 | F5: =B5*C5*'Premium Calculation'!$B$9 -> 40.277783 | G5: =B5*C5*'Premium Calculation'!$B$14 -> 0 | H5: =F5-G5 -> 40.277783 | I5: =B5*(Assumptions!$C$10*(1+Assumptions!$C$5)^(A5-1)+IF(A5=1,Assumptions!$C$9,0))*Assumptions!$C$23 -> 201.25889 | J5: =E5*(IF(A5=1,'Premium Calculation'!$B$32,Assumptions!$C$12)+Assumptions!$C$24) -> 24.737013 | K5: =B5*'Premium Calculation'!$B$14*Assumptions!$C$15 -> 0 | L5: =E5-H5-I5-J5-K5 -> 228.46657 | M5: =(1+Assumptions!$C$6+Assumptions!$C$25)^(-A5) -> 0.9335107 | N5: =L5*M5 -> 213.27599 | O5: =B5*M5 -> 0.82114218 | P5: =O5*(IF(A5=1,'Premium Calculation'!$B$32,Assumptions!$C$12)+Assumptions!$C$24) -> 0.041057109 | Q5: =(H5+I5+K5)*M5 -> 225.47707 | R5: =B5-S5-T5 -> 0.78954428 | S5: =B5*C5 -> 0.00040277783 | T5: =(B5-S5)*D5 -> 0.089680976 | U5: =B5-R5-S5-T5 -> 0
A6: 3 | B6: =IF(A6<='Premium Calculation'!$B$8,R5,0) -> 0.78954428 | C6: {=IF(B6=0,0,_xlfn.XLOOKUP('Premium Calculation'!$B$4+A6-1,Mortality!$A$4:$A$64,_xlfn.XLOOKUP('Premium Calculation'!$B$5&" "&'Premium Calculation'!$B$6,Mortality!$B$3:$E$3,Mortality!$B$4:$E$64))*IF('Premium Calculation'!$B$7="Preferred",Assumptions!$C$30,IF('Premium Calculation'!$B$7="Rated",Assumptions!$C$31,1))*Assumptions!$C$21)} -> 0.00049603241 | D6: =IF(B6=0,0,MIN(1,MAX(Assumptions!$C$27,Assumptions!$C$13*Assumptions!$C$28^(A6-1))*Assumptions!$C$22)) -> 0.0867 | E6: =B6*'Premium Calculation'!$B$29 -> 444.07332 | F6: =B6*C6*'Premium Calculation'!$B$9 -> 39.163955 | G6: =B6*C6*'Premium Calculation'!$B$14 -> 0 | H6: =F6-G6 -> 39.163955 | I6: =B6*(Assumptions!$C$10*(1+Assumptions!$C$5)^(A6-1)+IF(A6=1,Assumptions!$C$9,0))*Assumptions!$C$23 -> 187.87364 | J6: =E6*(IF(A6=1,'Premium Calculation'!$B$32,Assumptions!$C$12)+Assumptions!$C$24) -> 22.203666 | K6: =B6*'Premium Calculation'!$B$14*Assumptions!$C$15 -> 0 | L6: =E6-H6-I6-J6-K6 -> 194.83206 | M6: =(1+Assumptions!$C$6+Assumptions!$C$25)^(-A6) -> 0.90194271 | N6: =L6*M6 -> 175.72736 | O6: =B6*M6 -> 0.7121237 | P6: =O6*(IF(A6=1,'Premium Calculation'!$B$32,Assumptions!$C$12)+Assumptions!$C$24) -> 0.035606185 | Q6: =(H6+I6+K6)*M6 -> 204.7749 | R6: =B6-S6-T6 -> 0.7207331 | S6: =B6*C6 -> 0.00039163955 | T6: =(B6-S6)*D6 -> 0.068419534 | U6: =B6-R6-S6-T6 -> 0
A7: 4 | B7: =IF(A7<='Premium Calculation'!$B$8,R6,0) -> 0.7207331 | C7: {=IF(B7=0,0,_xlfn.XLOOKUP('Premium Calculation'!$B$4+A7-1,Mortality!$A$4:$A$64,_xlfn.XLOOKUP('Premium Calculation'!$B$5&" "&'Premium Calculation'!$B$6,Mortality!$B$3:$E$3,Mortality!$B$4:$E$64))*IF('Premium Calculation'!$B$7="Preferred",Assumptions!$C$30,IF('Premium Calculation'!$B$7="Rated",Assumptions!$C$31,1))*Assumptions!$C$21)} -> 0.00053734549 | D7: =IF(B7=0,0,MIN(1,MAX(Assumptions!$C$27,Assumptions!$C$13*Assumptions!$C$28^(A7-1))*Assumptions!$C$22)) -> 0.073695 | E7: =B7*'Premium Calculation'!$B$29 -> 405.37099 | F7: =B7*C7*'Premium Calculation'!$B$9 -> 38.728268 | G7: =B7*C7*'Premium Calculation'!$B$14 -> 0 | H7: =F7-G7 -> 38.728268 | I7: =B7*(Assumptions!$C$10*(1+Assumptions!$C$5)^(A7-1)+IF(A7=1,Assumptions!$C$9,0))*Assumptions!$C$23 -> 178.35988 | J7: =E7*(IF(A7=1,'Premium Calculation'!$B$32,Assumptions!$C$12)+Assumptions!$C$24) -> 20.268549 | K7: =B7*'Premium Calculation'!$B$14*Assumptions!$C$15 -> 0 | L7: =E7-H7-I7-J7-K7 -> 168.01429 | M7: =(1+Assumptions!$C$6+Assumptions!$C$25)^(-A7) -> 0.87144223 | N7: =L7*M7 -> 146.41475 | O7: =B7*M7 -> 0.62807726 | P7: =O7*(IF(A7=1,'Premium Calculation'!$B$32,Assumptions!$C$12)+Assumptions!$C$24) -> 0.031403863 | Q7: =(H7+I7+K7)*M7 -> 189.17978 | R7: =B7-S7-T7 -> 0.66725994 | S7: =B7*C7 -> 0.00038728268 | T7: =(B7-S7)*D7 -> 0.053085885 | U7: =B7-R7-S7-T7 -> 0
A8: 5 | B8: =IF(A8<='Premium Calculation'!$B$8,R7,0) -> 0.66725994 | C8: {=IF(B8=0,0,_xlfn.XLOOKUP('Premium Calculation'!$B$4+A8-1,Mortality!$A$4:$A$64,_xlfn.XLOOKUP('Premium Calculation'!$B$5&" "&'Premium Calculation'!$B$6,Mortality!$B$3:$E$3,Mortality!$B$4:$E$64))*IF('Premium Calculation'!$B$7="Preferred",Assumptions!$C$30,IF('Premium Calculation'!$B$7="Rated",Assumptions!$C$31,1))*Assumptions!$C$21)} -> 0.00058209942 | D8: =IF(B8=0,0,MIN(1,MAX(Assumptions!$C$27,Assumptions!$C$13*Assumptions!$C$28^(A8-1))*Assumptions!$C$22)) -> 0.06264075 | E8: =B8*'Premium Calculation'!$B$29 -> 375.2954 | F8: =B8*C8*'Premium Calculation'!$B$9 -> 38.841162 | G8: =B8*C8*'Premium Calculation'!$B$14 -> 0 | H8: =F8-G8 -> 38.841162 | I8: =B8*(Assumptions!$C$10*(1+Assumptions!$C$5)^(A8-1)+IF(A8=1,Assumptions!$C$9,0))*Assumptions!$C$23 -> 171.73194 | J8: =E8*(IF(A8=1,'Premium Calculation'!$B$32,Assumptions!$C$12)+Assumptions!$C$24) -> 18.76477 | K8: =B8*'Premium Calculation'!$B$14*Assumptions!$C$15 -> 0 | L8: =E8-H8-I8-J8-K8 -> 145.95753 | M8: =(1+Assumptions!$C$6+Assumptions!$C$25)^(-A8) -> 0.84197317 | N8: =L8*M8 -> 122.89232 | O8: =B8*M8 -> 0.56181496 | P8: =O8*(IF(A8=1,'Premium Calculation'!$B$32,Assumptions!$C$12)+Assumptions!$C$24) -> 0.028090748 | Q8: =(H8+I8+K8)*M8 -> 177.29691 | R8: =B8-S8-T8 -> 0.62509819 | S8: =B8*C8 -> 0.00038841162 | T8: =(B8-S8)*D8 -> 0.041773332 | U8: =B8-R8-S8-T8 -> 0
A9: 6 | B9: =IF(A9<='Premium Calculation'!$B$8,R8,0) -> 0.62509819 | C9: {=IF(B9=0,0,_xlfn.XLOOKUP('Premium Calculation'!$B$4+A9-1,Mortality!$A$4:$A$64,_xlfn.XLOOKUP('Premium Calculation'!$B$5&" "&'Premium Calculation'!$B$6,Mortality!$B$3:$E$3,Mortality!$B$4:$E$64))*IF('Premium Calculation'!$B$7="Preferred",Assumptions!$C$30,IF('Premium Calculation'!$B$7="Rated",Assumptions!$C$31,1))*Assumptions!$C$21)} -> 0.00063058078 | D9: =IF(B9=0,0,MIN(1,MAX(Assumptions!$C$27,Assumptions!$C$13*Assumptions!$C$28^(A9-1))*Assumptions!$C$22)) -> 0.053244637 | E9: =B9*'Premium Calculation'!$B$29 -> 351.58184 | F9: =B9*C9*'Premium Calculation'!$B$9 -> 39.41749 | G9: =B9*C9*'Premium Calculation'!$B$14 -> 0 | H9: =F9-G9 -> 39.41749 | I9: =B9*(Assumptions!$C$10*(1+Assumptions!$C$5)^(A9-1)+IF(A9=1,Assumptions!$C$9,0))*Assumptions!$C$23 -> 167.31606 | J9: =E9*(IF(A9=1,'Premium Calculation'!$B$32,Assumptions!$C$12)+Assumptions!$C$24) -> 17.579092 | K9: =B9*'Premium Calculation'!$B$14*Assumptions!$C$15 -> 0 | L9: =E9-H9-I9-J9-K9 -> 127.2692 | M9: =(1+Assumptions!$C$6+Assumptions!$C$25)^(-A9) -> 0.81350064 | N9: =L9*M9 -> 103.53358 | O9: =B9*M9 -> 0.50851778 | P9: =O9*(IF(A9=1,'Premium Calculation'!$B$32,Assumptions!$C$12)+Assumptions!$C$24) -> 0.025425889 | Q9: =(H9+I9+K9)*M9 -> 168.17787 | R9: =B9-S9-T9 -> 0.59144188 | S9: =B9*C9 -> 0.0003941749 | T9: =(B9-S9)*D9 -> 0.033262139 | U9: =B9-R9-S9-T9 -> -5.5511151e-17
A10: 7 | B10: =IF(A10<='Premium Calculation'!$B$8,R9,0) -> 0.59144188 | C10: {=IF(B10=0,0,_xlfn.XLOOKUP('Premium Calculation'!$B$4+A10-1,Mortality!$A$4:$A$64,_xlfn.XLOOKUP('Premium Calculation'!$B$5&" "&'Premium Calculation'!$B$6,Mortality!$B$3:$E$3,Mortality!$B$4:$E$64))*IF('Premium Calculation'!$B$7="Preferred",Assumptions!$C$30,IF('Premium Calculation'!$B$7="Rated",Assumptions!$C$31,1))*Assumptions!$C$21)} -> 0.0006831 | D10: =IF(B10=0,0,MIN(1,MAX(Assumptions!$C$27,Assumptions!$C$13*Assumptions!$C$28^(A10-1))*Assumptions!$C$22)) -> 0.045257942 | E10: =B10*'Premium Calculation'!$B$29 -> 332.6521 | F10: =B10*C10*'Premium Calculation'!$B$9 -> 40.401395 | G10: =B10*C10*'Premium Calculation'!$B$14 -> 0 | H10: =F10-G10 -> 40.401395 | I10: =B10*(Assumptions!$C$10*(1+Assumptions!$C$5)^(A10-1)+IF(A10=1,Assumptions!$C$9,0))*Assumptions!$C$23 -> 164.63978 | J10: =E10*(IF(A10=1,'Premium Calculation'!$B$32,Assumptions!$C$12)+Assumptions!$C$24) -> 16.632605 | K10: =B10*'Premium Calculation'!$B$14*Assumptions!$C$15 -> 0 | L10: =E10-H10-I10-J10-K10 -> 110.97831 | M10: =(1+Assumptions!$C$6+Assumptions!$C$25)^(-A10) -> 0.78599096 | N10: =L10*M10 -> 87.227952 | O10: =B10*M10 -> 0.46486797 | P10: =O10*(IF(A10=1,'Premium Calculation'!$B$32,Assumptions!$C$12)+Assumptions!$C$24) -> 0.023243399 | Q10: =(H10+I10+K10)*M10 -> 161.16051 | R10: =B10-S10-T10 -> 0.56428871 | S10: =B10*C10 -> 0.00040401395 | T10: =(B10-S10)*D10 -> 0.026749157 | U10: =B10-R10-S10-T10 -> 0
A11: 8 | B11: =IF(A11<='Premium Calculation'!$B$8,R10,0) -> 0.56428871 | C11: {=IF(B11=0,0,_xlfn.XLOOKUP('Premium Calculation'!$B$4+A11-1,Mortality!$A$4:$A$64,_xlfn.XLOOKUP('Premium Calculation'!$B$5&" "&'Premium Calculation'!$B$6,Mortality!$B$3:$E$3,Mortality!$B$4:$E$64))*IF('Premium Calculation'!$B$7="Preferred",Assumptions!$C$30,IF('Premium Calculation'!$B$7="Rated",Assumptions!$C$31,1))*Assumptions!$C$21)} -> 0.0007399934 | D11: =IF(B11=0,0,MIN(1,MAX(Assumptions!$C$27,Assumptions!$C$13*Assumptions!$C$28^(A11-1))*Assumptions!$C$22)) -> 0.038469251 | E11: =B11*'Premium Calculation'!$B$29 -> 317.38 | F11: =B11*C11*'Premium Calculation'!$B$9 -> 41.756992 | G11: =B11*C11*'Premium Calculation'!$B$14 -> 0 | H11: =F11-G11 -> 41.756992 | I11: =B11*(Assumptions!$C$10*(1+Assumptions!$C$5)^(A11-1)+IF(A11=1,Assumptions!$C$9,0))*Assumptions!$C$23 -> 163.3644 | J11: =E11*(IF(A11=1,'Premium Calculation'!$B$32,Assumptions!$C$12)+Assumptions!$C$24) -> 15.869 | K11: =B11*'Premium Calculation'!$B$14*Assumptions!$C$15 -> 0 | L11: =E11-H11-I11-J11-K11 -> 96.38961 | M11: =(1+Assumptions!$C$6+Assumptions!$C$25)^(-A11) -> 0.75941156 | N11: =L11*M11 -> 73.199383 | O11: =B11*M11 -> 0.42852737 | P11: =O11*(IF(A11=1,'Premium Calculation'!$B$32,Assumptions!$C$12)+Assumptions!$C$24) -> 0.021426368 | Q11: =(H11+I11+K11)*M11 -> 155.77155 | R11: =B11-S11-T11 -> 0.54217944 | S11: =B11*C11 -> 0.00041756992 | T11: =(B11-S11)*D11 -> 0.0216917 | U11: =B11-R11-S11-T11 -> -5.8980598e-17
A12: 9 | B12: =IF(A12<='Premium Calculation'!$B$8,R11,0) -> 0.54217944 | C12: {=IF(B12=0,0,_xlfn.XLOOKUP('Premium Calculation'!$B$4+A12-1,Mortality!$A$4:$A$64,_xlfn.XLOOKUP('Premium Calculation'!$B$5&" "&'Premium Calculation'!$B$6,Mortality!$B$3:$E$3,Mortality!$B$4:$E$64))*IF('Premium Calculation'!$B$7="Preferred",Assumptions!$C$30,IF('Premium Calculation'!$B$7="Rated",Assumptions!$C$31,1))*Assumptions!$C$21)} -> 0.00080162528 | D12: =IF(B12=0,0,MIN(1,MAX(Assumptions!$C$27,Assumptions!$C$13*Assumptions!$C$28^(A12-1))*Assumptions!$C$22)) -> 0.032698863 | E12: =B12*'Premium Calculation'!$B$29 -> 304.9448 | F12: =B12*C12*'Premium Calculation'!$B$9 -> 43.462474 | G12: =B12*C12*'Premium Calculation'!$B$14 -> 0 | H12: =F12-G12 -> 43.462474 | I12: =B12*(Assumptions!$C$10*(1+Assumptions!$C$5)^(A12-1)+IF(A12=1,Assumptions!$C$9,0))*Assumptions!$C$23 -> 163.2422 | J12: =E12*(IF(A12=1,'Premium Calculation'!$B$32,Assumptions!$C$12)+Assumptions!$C$24) -> 15.24724 | K12: =B12*'Premium Calculation'!$B$14*Assumptions!$C$15 -> 0 | L12: =E12-H12-I12-J12-K12 -> 82.99289 | M12: =(1+Assumptions!$C$6+Assumptions!$C$25)^(-A12) -> 0.73373097 | N12: =L12*M12 -> 60.894454 | O12: =B12*M12 -> 0.39781385 | P12: =O12*(IF(A12=1,'Premium Calculation'!$B$32,Assumptions!$C$12)+Assumptions!$C$24) -> 0.019890692 | Q12: =(H12+I12+K12)*M12 -> 151.66562 | R12: =B12-S12-T12 -> 0.52403037 | S12: =B12*C12 -> 0.00043462474 | T12: =(B12-S12)*D12 -> 0.017714439 | U12: =B12-R12-S12-T12 -> 0
A13: 10 | B13: =IF(A13<='Premium Calculation'!$B$8,R12,0) -> 0.52403037 | C13: {=IF(B13=0,0,_xlfn.XLOOKUP('Premium Calculation'!$B$4+A13-1,Mortality!$A$4:$A$64,_xlfn.XLOOKUP('Premium Calculation'!$B$5&" "&'Premium Calculation'!$B$6,Mortality!$B$3:$E$3,Mortality!$B$4:$E$64))*IF('Premium Calculation'!$B$7="Preferred",Assumptions!$C$30,IF('Premium Calculation'!$B$7="Rated",Assumptions!$C$31,1))*Assumptions!$C$21)} -> 0.00086839029 | D13: =IF(B13=0,0,MIN(1,MAX(Assumptions!$C$27,Assumptions!$C$13*Assumptions!$C$28^(A13-1))*Assumptions!$C$22)) -> 0.027794034 | E13: =B13*'Premium Calculation'!$B$29 -> 294.737 | F13: =B13*C13*'Premium Calculation'!$B$9 -> 45.506289 | G13: =B13*C13*'Premium Calculation'!$B$14 -> 0 | H13: =F13-G13 -> 45.506289 | I13: =B13*(Assumptions!$C$10*(1+Assumptions!$C$5)^(A13-1)+IF(A13=1,Assumptions!$C$9,0))*Assumptions!$C$23 -> 164.0889 | J13: =E13*(IF(A13=1,'Premium Calculation'!$B$32,Assumptions!$C$12)+Assumptions!$C$24) -> 14.73685 | K13: =B13*'Premium Calculation'!$B$14*Assumptions!$C$15 -> 0 | L13: =E13-H13-I13-J13-K13 -> 70.404962 | M13: =(1+Assumptions!$C$6+Assumptions!$C$25)^(-A13) -> 0.70891881 | N13: =L13*M13 -> 49.911402 | O13: =B13*M13 -> 0.37149499 | P13: =O13*(IF(A13=1,'Premium Calculation'!$B$32,Assumptions!$C$12)+Assumptions!$C$24) -> 0.01857475 | Q13: =(H13+I13+K13)*M13 -> 148.58597 | R13: =B13-S13-T13 -> 0.50902304 | S13: =B13*C13 -> 0.00045506289 | T13: =(B13-S13)*D13 -> 0.01455227 | U13: =B13-R13-S13-T13 -> 2.6020852e-17
A14: 11 | B14: =IF(A14<='Premium Calculation'!$B$8,R13,0) -> 0 | C14: {=IF(B14=0,0,_xlfn.XLOOKUP('Premium Calculation'!$B$4+A14-1,Mortality!$A$4:$A$64,_xlfn.XLOOKUP('Premium Calculation'!$B$5&" "&'Premium Calculation'!$B$6,Mortality!$B$3:$E$3,Mortality!$B$4:$E$64))*IF('Premium Calculation'!$B$7="Preferred",Assumptions!$C$30,IF('Premium Calculation'!$B$7="Rated",Assumptions!$C$31,1))*Assumptions!$C$21)} -> 0 | D14: =IF(B14=0,0,MIN(1,MAX(Assumptions!$C$27,Assumptions!$C$13*Assumptions!$C$28^(A14-1))*Assumptions!$C$22)) -> 0 | E14: =B14*'Premium Calculation'!$B$29 -> 0 | F14: =B14*C14*'Premium Calculation'!$B$9 -> 0 | G14: =B14*C14*'Premium Calculation'!$B$14 -> 0 | H14: =F14-G14 -> 0 | I14: =B14*(Assumptions!$C$10*(1+Assumptions!$C$5)^(A14-1)+IF(A14=1,Assumptions!$C$9,0))*Assumptions!$C$23 -> 0 | J14: =E14*(IF(A14=1,'Premium Calculation'!$B$32,Assumptions!$C$12)+Assumptions!$C$24) -> 0 | K14: =B14*'Premium Calculation'!$B$14*Assumptions!$C$15 -> 0 | L14: =E14-H14-I14-J14-K14 -> 0 | M14: =(1+Assumptions!$C$6+Assumptions!$C$25)^(-A14) -> 0.68494571 | N14: =L14*M14 -> 0 | O14: =B14*M14 -> 0 | P14: =O14*(IF(A14=1,'Premium Calculation'!$B$32,Assumptions!$C$12)+Assumptions!$C$24) -> 0 | Q14: =(H14+I14+K14)*M14 -> 0 | R14: =B14-S14-T14 -> 0 | S14: =B14*C14 -> 0 | T14: =(B14-S14)*D14 -> 0 | U14: =B14-R14-S14-T14 -> 0
A15: 12 | B15: =IF(A15<='Premium Calculation'!$B$8,R14,0) -> 0 | C15: {=IF(B15=0,0,_xlfn.XLOOKUP('Premium Calculation'!$B$4+A15-1,Mortality!$A$4:$A$64,_xlfn.XLOOKUP('Premium Calculation'!$B$5&" "&'Premium Calculation'!$B$6,Mortality!$B$3:$E$3,Mortality!$B$4:$E$64))*IF('Premium Calculation'!$B$7="Preferred",Assumptions!$C$30,IF('Premium Calculation'!$B$7="Rated",Assumptions!$C$31,1))*Assumptions!$C$21)} -> 0 | D15: =IF(B15=0,0,MIN(1,MAX(Assumptions!$C$27,Assumptions!$C$13*Assumptions!$C$28^(A15-1))*Assumptions!$C$22)) -> 0 | E15: =B15*'Premium Calculation'!$B$29 -> 0 | F15: =B15*C15*'Premium Calculation'!$B$9 -> 0 | G15: =B15*C15*'Premium Calculation'!$B$14 -> 0 | H15: =F15-G15 -> 0 | I15: =B15*(Assumptions!$C$10*(1+Assumptions!$C$5)^(A15-1)+IF(A15=1,Assumptions!$C$9,0))*Assumptions!$C$23 -> 0 | J15: =E15*(IF(A15=1,'Premium Calculation'!$B$32,Assumptions!$C$12)+Assumptions!$C$24) -> 0 | K15: =B15*'Premium Calculation'!$B$14*Assumptions!$C$15 -> 0 | L15: =E15-H15-I15-J15-K15 -> 0 | M15: =(1+Assumptions!$C$6+Assumptions!$C$25)^(-A15) -> 0.6617833 | N15: =L15*M15 -> 0 | O15: =B15*M15 -> 0 | P15: =O15*(IF(A15=1,'Premium Calculation'!$B$32,Assumptions!$C$12)+Assumptions!$C$24) -> 0 | Q15: =(H15+I15+K15)*M15 -> 0 | R15: =B15-S15-T15 -> 0 | S15: =B15*C15 -> 0 | T15: =(B15-S15)*D15 -> 0 | U15: =B15-R15-S15-T15 -> 0
A16: 13 | B16: =IF(A16<='Premium Calculation'!$B$8,R15,0) -> 0 | C16: {=IF(B16=0,0,_xlfn.XLOOKUP('Premium Calculation'!$B$4+A16-1,Mortality!$A$4:$A$64,_xlfn.XLOOKUP('Premium Calculation'!$B$5&" "&'Premium Calculation'!$B$6,Mortality!$B$3:$E$3,Mortality!$B$4:$E$64))*IF('Premium Calculation'!$B$7="Preferred",Assumptions!$C$30,IF('Premium Calculation'!$B$7="Rated",Assumptions!$C$31,1))*Assumptions!$C$21)} -> 0 | D16: =IF(B16=0,0,MIN(1,MAX(Assumptions!$C$27,Assumptions!$C$13*Assumptions!$C$28^(A16-1))*Assumptions!$C$22)) -> 0 | E16: =B16*'Premium Calculation'!$B$29 -> 0 | F16: =B16*C16*'Premium Calculation'!$B$9 -> 0 | G16: =B16*C16*'Premium Calculation'!$B$14 -> 0 | H16: =F16-G16 -> 0 | I16: =B16*(Assumptions!$C$10*(1+Assumptions!$C$5)^(A16-1)+IF(A16=1,Assumptions!$C$9,0))*Assumptions!$C$23 -> 0 | J16: =E16*(IF(A16=1,'Premium Calculation'!$B$32,Assumptions!$C$12)+Assumptions!$C$24) -> 0 | K16: =B16*'Premium Calculation'!$B$14*Assumptions!$C$15 -> 0 | L16: =E16-H16-I16-J16-K16 -> 0 | M16: =(1+Assumptions!$C$6+Assumptions!$C$25)^(-A16) -> 0.63940415 | N16: =L16*M16 -> 0 | O16: =B16*M16 -> 0 | P16: =O16*(IF(A16=1,'Premium Calculation'!$B$32,Assumptions!$C$12)+Assumptions!$C$24) -> 0 | Q16: =(H16+I16+K16)*M16 -> 0 | R16: =B16-S16-T16 -> 0 | S16: =B16*C16 -> 0 | T16: =(B16-S16)*D16 -> 0 | U16: =B16-R16-S16-T16 -> 0
... A43: 40 | B43: =IF(A43<='Premium Calculation'!$B$8,R42,0) -> 0 | C43: {=IF(B43=0,0,_xlfn.XLOOKUP('Premium Calculation'!$B$4+A43-1,Mortality!$A$4:$A$64,_xlfn.XLOOKUP('Premium Calculation'!$B$5&" "&'Premium Calculation'!$B$6,Mortality!$B$3:$E$3,Mortality!$B$4:$E$64))*IF('Premium Calculation'!$B$7="Preferred",Assumptions!$C$30,IF('Premium Calculation'!$B$7="Rated",Assumptions!$C$31,1))*Assumptions!$C$21)} -> 0 | D43: =IF(B43=0,0,MIN(1,MAX(Assumptions!$C$27,Assumptions!$C$13*Assumptions!$C$28^(A43-1))*Assumptions!$C$22)) -> 0 | E43: =B43*'Premium Calculation'!$B$29 -> 0 | F43: =B43*C43*'Premium Calculation'!$B$9 -> 0 | G43: =B43*C43*'Premium Calculation'!$B$14 -> 0 | H43: =F43-G43 -> 0 | I43: =B43*(Assumptions!$C$10*(1+Assumptions!$C$5)^(A43-1)+IF(A43=1,Assumptions!$C$9,0))*Assumptions!$C$23 -> 0 | J43: =E43*(IF(A43=1,'Premium Calculation'!$B$32,Assumptions!$C$12)+Assumptions!$C$24) -> 0 | K43: =B43*'Premium Calculation'!$B$14*Assumptions!$C$15 -> 0 | L43: =E43-H43-I43-J43-K43 -> 0 | M43: =(1+Assumptions!$C$6+Assumptions!$C$25)^(-A43) -> 0.25257247 | N43: =L43*M43 -> 0 | O43: =B43*M43 -> 0 | P43: =O43*(IF(A43=1,'Premium Calculation'!$B$32,Assumptions!$C$12)+Assumptions!$C$24) -> 0 | Q43: =(H43+I43+K43)*M43 -> 0 | R43: =B43-S43-T43 -> 0 | S43: =B43*C43 -> 0 | T43: =(B43-S43)*D43 -> 0 | U43: =B43-R43-S43-T43 -> 0
A46: Annual projection with financial cash flows assumed at year end. Death is applied before lapses, and no surrender benefit is assumed for the term policy.

Sheet Reinsurance
A1: Reinsurance
A3: Metric | B3: Gross | C3: Ceded | D3: Net / retained | E3: Unit | F3: Comment
A4: Sum assured | B4: ='Premium Calculation'!B9 -> 100000 | C4: ='Premium Calculation'!B14 -> 0 | D4: =B4-C4 -> 100000 | E4: AED | F4: Amount above the retention limit is ceded
A5: Expected Year 1 claim | B5: =Cashflows!F4 -> 42.269093 | C5: =Cashflows!G4 -> 0 | D5: =Cashflows!H4 -> 42.269093 | E5: AED | F5: Expected claim cost in Year 1
A6: Year 1 reinsurance premium | B6: - | C6: =Cashflows!K4 -> 0 | D6: =-C6 -> 0 | E6: AED | F6: Cost of reinsurance
A7: Year 1 claim and reinsurance cost | B7: =Cashflows!F4 -> 42.269093 | C7: =Cashflows!G4-Cashflows!K4 -> 0 | D7: =B7-C7 -> 42.269093 | E7: AED | F7: Claims and reinsurance premium combined
A9: PV reinsurance recoveries | B9: =SUMPRODUCT(Cashflows!G4:G43,Cashflows!M4:M43) -> 0
A10: PV reinsurance premiums | B10: =SUMPRODUCT(Cashflows!K4:K43,Cashflows!M4:M43) -> 0
A11: Reinsurance impact on PVFP | B11: =B9-B10 -> 0
A12: PVFP without reinsurance | B12: ='Profit Testing'!B7-B11 -> 344.85011
A15: This section compares the economic impact of reinsurance on projected cash flows. Separate IFRS 17 accounting for reinsurance contracts held is not included.

Sheet Profit Testing
A1: Profit Testing
A3: Metric | B3: Value | C3: Unit | D3: Definition | F3: Year | G3: Cumulative discounted profit | H3: Break-even reached?
A4: PV premiums | B4: =SUMPRODUCT(Cashflows!E4:E43,Cashflows!M4:M43) -> 3296.2306 | C4: AED | D4: Present value of projected premiums | F4: 1 | G4: =SUM(Cashflows!$N$4:N4) -> -688.22708 | H4: =IF(AND(F4<='Premium Calculation'!$B$8,G4>=0),"Yes","No") -> No
A5: PV retained claims | B5: =SUMPRODUCT(Cashflows!H4:H43,Cashflows!M4:M43) -> 339.89781 | C5: AED | D5: Expected claims after RI recoveries | F5: 2 | G5: =SUM(Cashflows!$N$4:N5) -> -474.95109 | H5: =IF(AND(F5<='Premium Calculation'!$B$8,G5>=0),"Yes","No") -> No
A6: PV other outgo | B6: =SUMPRODUCT(Cashflows!I4:I43,Cashflows!M4:M43)+SUMPRODUCT(Cashflows!J4:J43,Cashflows!M4:M43)+SUMPRODUCT(Cashflows!K4:K43,Cashflows!M4:M43) -> 2611.4826 | C6: AED | D6: Expenses, commission and RI premiums | F6: 3 | G6: =SUM(Cashflows!$N$4:N6) -> -299.22373 | H6: =IF(AND(F6<='Premium Calculation'!$B$8,G6>=0),"Yes","No") -> No
A7: PVFP | B7: =SUM(Cashflows!N4:N43) -> 344.85011 | C7: AED | D7: Present value of future profits, before tax and capital costs | F7: 4 | G7: =SUM(Cashflows!$N$4:N7) -> -152.80898 | H7: =IF(AND(F7<='Premium Calculation'!$B$8,G7>=0),"Yes","No") -> No
A8: NBM | B8: =IF(B4=0,"n.a.",B7/B4) -> 0.10461954 | C8: % | D8: PVFP / PV premiums | F8: 5 | G8: =SUM(Cashflows!$N$4:N8) -> -29.91666 | H8: =IF(AND(F8<='Premium Calculation'!$B$8,G8>=0),"Yes","No") -> No
A9: Break-even year | B9: =IF(COUNTIF(H4:H43,"Yes")=0,"Not reached",_xlfn.XLOOKUP("Yes",H4:H43,F4:F43)) -> 6 | D9: First non-negative cumulative discounted profit | F9: 6 | G9: =SUM(Cashflows!$N$4:N9) -> 73.616918 | H9: =IF(AND(F9<='Premium Calculation'!$B$8,G9>=0),"Yes","No") -> Yes
A10: Profit status | B10: =IF(B7>=0,"Non-negative","Loss-making") -> Non-negative | D10: Indicates whether PVFP is positive or negative | F10: 7 | G10: =SUM(Cashflows!$N$4:N10) -> 160.84487 | H10: =IF(AND(F10<='Premium Calculation'!$B$8,G10>=0),"Yes","No") -> Yes
A11: Profit reconciliation | B11: =B4-B5-B6-B7 -> -1.1937118e-12 | C11: AED | D11: Should be zero if the cash flows reconcile | F11: 8 | G11: =SUM(Cashflows!$N$4:N11) -> 234.04425 | H11: =IF(AND(F11<='Premium Calculation'!$B$8,G11>=0),"Yes","No") -> Yes
F12: 9 | G12: =SUM(Cashflows!$N$4:N12) -> 294.93871 | H12: =IF(AND(F12<='Premium Calculation'!$B$8,G12>=0),"Yes","No") -> Yes
F13: 10 | G13: =SUM(Cashflows!$N$4:N13) -> 344.85011 | H13: =IF(AND(F13<='Premium Calculation'!$B$8,G13>=0),"Yes","No") -> Yes
A14: Financial cash flows are assumed to occur at year end in this annual projection. | F14: 11 | G14: =SUM(Cashflows!$N$4:N14) -> 344.85011 | H14: =IF(AND(F14<='Premium Calculation'!$B$8,G14>=0),"Yes","No") -> No
F15: 12 | G15: =SUM(Cashflows!$N$4:N15) -> 344.85011 | H15: =IF(AND(F15<='Premium Calculation'!$B$8,G15>=0),"Yes","No") -> No
A16: PVFP is calculated after RI and before tax and capital costs. | F16: 13 | G16: =SUM(Cashflows!$N$4:N16) -> 344.85011 | H16: =IF(AND(F16<='Premium Calculation'!$B$8,G16>=0),"Yes","No") -> No
F17: 14 | G17: =SUM(Cashflows!$N$4:N17) -> 344.85011 | H17: =IF(AND(F17<='Premium Calculation'!$B$8,G17>=0),"Yes","No") -> No
A18: NBM = PVFP / PV premiums. Break-even uses discounted profits. | F18: 15 | G18: =SUM(Cashflows!$N$4:N18) -> 344.85011 | H18: =IF(AND(F18<='Premium Calculation'!$B$8,G18>=0),"Yes","No") -> No
F19: 16 | G19: =SUM(Cashflows!$N$4:N19) -> 344.85011 | H19: =IF(AND(F19<='Premium Calculation'!$B$8,G19>=0),"Yes","No") -> No
F20: 17 | G20: =SUM(Cashflows!$N$4:N20) -> 344.85011 | H20: =IF(AND(F20<='Premium Calculation'!$B$8,G20>=0),"Yes","No") -> No
F21: 18 | G21: =SUM(Cashflows!$N$4:N21) -> 344.85011 | H21: =IF(AND(F21<='Premium Calculation'!$B$8,G21>=0),"Yes","No") -> No
F22: 19 | G22: =SUM(Cashflows!$N$4:N22) -> 344.85011 | H22: =IF(AND(F22<='Premium Calculation'!$B$8,G22>=0),"Yes","No") -> No
F23: 20 | G23: =SUM(Cashflows!$N$4:N23) -> 344.85011 | H23: =IF(AND(F23<='Premium Calculation'!$B$8,G23>=0),"Yes","No") -> No
F24: 21 | G24: =SUM(Cashflows!$N$4:N24) -> 344.85011 | H24: =IF(AND(F24<='Premium Calculation'!$B$8,G24>=0),"Yes","No") -> No
F25: 22 | G25: =SUM(Cashflows!$N$4:N25) -> 344.85011 | H25: =IF(AND(F25<='Premium Calculation'!$B$8,G25>=0),"Yes","No") -> No
F26: 23 | G26: =SUM(Cashflows!$N$4:N26) -> 344.85011 | H26: =IF(AND(F26<='Premium Calculation'!$B$8,G26>=0),"Yes","No") -> No
F27: 24 | G27: =SUM(Cashflows!$N$4:N27) -> 344.85011 | H27: =IF(AND(F27<='Premium Calculation'!$B$8,G27>=0),"Yes","No") -> No
F28: 25 | G28: =SUM(Cashflows!$N$4:N28) -> 344.85011 | H28: =IF(AND(F28<='Premium Calculation'!$B$8,G28>=0),"Yes","No") -> No
F29: 26 | G29: =SUM(Cashflows!$N$4:N29) -> 344.85011 | H29: =IF(AND(F29<='Premium Calculation'!$B$8,G29>=0),"Yes","No") -> No
F30: 27 | G30: =SUM(Cashflows!$N$4:N30) -> 344.85011 | H30: =IF(AND(F30<='Premium Calculation'!$B$8,G30>=0),"Yes","No") -> No
... F43: 40 | G43: =SUM(Cashflows!$N$4:N43) -> 344.85011 | H43: =IF(AND(F43<='Premium Calculation'!$B$8,G43>=0),"Yes","No") -> No

Sheet Portfolio Analysis
A1: Portfolio Analysis
A2: Analysis of profitability across the synthetic term life portfolio.
A3: Results are compared across key policy and customer segments to identify differences in premium adequacy and profitability.
A5: Portfolio observations
A6: Segment | C6: Lowest NBM | E6: NBM | F6: Highest NBM | H6: NBM | I6: Loss-making policies
A7: Channel | C7: =_xlfn.XLOOKUP(MIN($H$19:$H$21),$H$19:$H$21,$A$19:$A$21) -> Direct | E7: =MIN($H$19:$H$21) -> 0.027449464 | F7: =_xlfn.XLOOKUP(MAX($H$19:$H$21),$H$19:$H$21,$A$19:$A$21) -> Bancassurance | H7: =MAX($H$19:$H$21) -> 0.11053529 | I7: =_xlfn.XLOOKUP(MIN($H$19:$H$21),$H$19:$H$21,$I$19:$I$21)&" of "&_xlfn.XLOOKUP(MIN($H$19:$H$21),$H$19:$H$21,$B$19:$B$21) -> 20 of 52
A8: Entry-age band | C8: =_xlfn.XLOOKUP(MIN($H$26:$H$30),$H$26:$H$30,$A$26:$A$30) -> 50-59 | E8: =MIN($H$26:$H$30) -> -0.081048407 | F8: =_xlfn.XLOOKUP(MAX($H$26:$H$30),$H$26:$H$30,$A$26:$A$30) -> 20-29 | H8: =MAX($H$26:$H$30) -> 0.23642095 | I8: =_xlfn.XLOOKUP(MIN($H$26:$H$30),$H$26:$H$30,$I$26:$I$30)&" of "&_xlfn.XLOOKUP(MIN($H$26:$H$30),$H$26:$H$30,$B$26:$B$30) -> 25 of 32
A9: Sex | C9: =_xlfn.XLOOKUP(MIN($H$35:$H$36),$H$35:$H$36,$A$35:$A$36) -> Male | E9: =MIN($H$35:$H$36) -> 0.067523529 | F9: =_xlfn.XLOOKUP(MAX($H$35:$H$36),$H$35:$H$36,$A$35:$A$36) -> Female | H9: =MAX($H$35:$H$36) -> 0.10244139 | I9: =_xlfn.XLOOKUP(MIN($H$35:$H$36),$H$35:$H$36,$I$35:$I$36)&" of "&_xlfn.XLOOKUP(MIN($H$35:$H$36),$H$35:$H$36,$B$35:$B$36) -> 41 of 108
A10: Smoker status | C10: =_xlfn.XLOOKUP(MIN($H$41:$H$42),$H$41:$H$42,$A$41:$A$42) -> Smoker | E10: =MIN($H$41:$H$42) -> 0.059364413 | F10: =_xlfn.XLOOKUP(MAX($H$41:$H$42),$H$41:$H$42,$A$41:$A$42) -> Non-smoker | H10: =MAX($H$41:$H$42) -> 0.087001004 | I10: =_xlfn.XLOOKUP(MIN($H$41:$H$42),$H$41:$H$42,$I$41:$I$42)&" of "&_xlfn.XLOOKUP(MIN($H$41:$H$42),$H$41:$H$42,$B$41:$B$42) -> 16 of 33
A11: Underwriting class | C11: =_xlfn.XLOOKUP(MIN($H$47:$H$49),$H$47:$H$49,$A$47:$A$49) -> Rated | E11: =MIN($H$47:$H$49) -> 0.0083845365 | F11: =_xlfn.XLOOKUP(MAX($H$47:$H$49),$H$47:$H$49,$A$47:$A$49) -> Standard | H11: =MAX($H$47:$H$49) -> 0.09284291 | I11: =_xlfn.XLOOKUP(MIN($H$47:$H$49),$H$47:$H$49,$I$47:$I$49)&" of "&_xlfn.XLOOKUP(MIN($H$47:$H$49),$H$47:$H$49,$B$47:$B$49) -> 9 of 19
A12: Sum-assured band (AED) | C12: =_xlfn.XLOOKUP(MIN($H$54:$H$57),$H$54:$H$57,$A$54:$A$57) -> 250k-500k | E12: =MIN($H$54:$H$57) -> -0.09855425 | F12: =_xlfn.XLOOKUP(MAX($H$54:$H$57),$H$54:$H$57,$A$54:$A$57) -> Over 1m | H12: =MAX($H$54:$H$57) -> 0.265673 | I12: =_xlfn.XLOOKUP(MIN($H$54:$H$57),$H$54:$H$57,$I$54:$I$57)&" of "&_xlfn.XLOOKUP(MIN($H$54:$H$57),$H$54:$H$57,$B$54:$B$57) -> 35 of 61
A13: Premium frequency | C13: =_xlfn.XLOOKUP(MIN($H$62:$H$63),$H$62:$H$63,$A$62:$A$63) -> Monthly | E13: =MIN($H$62:$H$63) -> 0.065369441 | F13: =_xlfn.XLOOKUP(MAX($H$62:$H$63),$H$62:$H$63,$A$62:$A$63) -> Annual | H13: =MAX($H$62:$H$63) -> 0.096804275 | I13: =_xlfn.XLOOKUP(MIN($H$62:$H$63),$H$62:$H$63,$I$62:$I$63)&" of "&_xlfn.XLOOKUP(MIN($H$62:$H$63),$H$62:$H$63,$B$62:$B$63) -> 38 of 93
A14: Policy term (years) | C14: =_xlfn.XLOOKUP(MIN($H$68:$H$71),$H$68:$H$71,$A$68:$A$71) -> 25 | E14: =MIN($H$68:$H$71) -> -0.061358489 | F14: =_xlfn.XLOOKUP(MAX($H$68:$H$71),$H$68:$H$71,$A$68:$A$71) -> 10 | H14: =MAX($H$68:$H$71) -> 0.1838517 | I14: =_xlfn.XLOOKUP(MIN($H$68:$H$71),$H$68:$H$71,$I$68:$I$71)&" of "&_xlfn.XLOOKUP(MIN($H$68:$H$71),$H$68:$H$71,$B$68:$B$71) -> 14 of 22
A17: By channel
A18: Channel | B18: Policies | C18: Charged prem. | D18: Technical prem. | E18: Adequacy | F18: PV premiums | G18: PVFP | H18: NBM | I18: Loss-making | J18: % loss-making | K18: Share of PVFP | L18: Profitability
A19: Direct | B19: =COUNTIFS('Policy Calculations'!$K$30:$K$279,$A19,'Policy Calculations'!$T$30:$T$279,1) -> 52 | C19: =SUMIFS('Policy Calculations'!$M$30:$M$279,'Policy Calculations'!$K$30:$K$279,$A19,'Policy Calculations'!$T$30:$T$279,1) -> 104688.1 | D19: =SUMIFS('Policy Calculations'!$AF$30:$AF$279,'Policy Calculations'!$K$30:$K$279,$A19,'Policy Calculations'!$T$30:$T$279,1) -> 112641.43 | E19: =IF(D19=0,"",C19/D19) -> 0.92939251 | F19: =SUMIFS('Policy Calculations'!$AH$30:$AH$279,'Policy Calculations'!$K$30:$K$279,$A19,'Policy Calculations'!$T$30:$T$279,1) -> 804459.56 | G19: =SUMIFS('Policy Calculations'!$AI$30:$AI$279,'Policy Calculations'!$K$30:$K$279,$A19,'Policy Calculations'!$T$30:$T$279,1) -> 22081.984 | H19: =IF(F19=0,"",G19/F19) -> 0.027449464 | I19: =COUNTIFS('Policy Calculations'!$K$30:$K$279,$A19,'Policy Calculations'!$AR$30:$AR$279,"Loss-making") -> 20 | J19: =IF(B19=0,"",I19/B19) -> 0.38461538 | K19: =IF('Portfolio Totals'!$B$13=0,"",G19/'Portfolio Totals'!$B$13) -> 0.086167796 | L19: =IF(B19=0,"No policies",IF(G19<0,"Loss-making segment",IF(H19<Assumptions!$C$16-0.00001,"Below target","At or above target"))) -> Below target
A20: Broker | B20: =COUNTIFS('Policy Calculations'!$K$30:$K$279,$A20,'Policy Calculations'!$T$30:$T$279,1) -> 52 | C20: =SUMIFS('Policy Calculations'!$M$30:$M$279,'Policy Calculations'!$K$30:$K$279,$A20,'Policy Calculations'!$T$30:$T$279,1) -> 137646.31 | D20: =SUMIFS('Policy Calculations'!$AF$30:$AF$279,'Policy Calculations'!$K$30:$K$279,$A20,'Policy Calculations'!$T$30:$T$279,1) -> 138784.98 | E20: =IF(D20=0,"",C20/D20) -> 0.99179547 | F20: =SUMIFS('Policy Calculations'!$AH$30:$AH$279,'Policy Calculations'!$K$30:$K$279,$A20,'Policy Calculations'!$T$30:$T$279,1) -> 1043157.6 | G20: =SUMIFS('Policy Calculations'!$AI$30:$AI$279,'Policy Calculations'!$K$30:$K$279,$A20,'Policy Calculations'!$T$30:$T$279,1) -> 84276.908 | H20: =IF(F20=0,"",G20/F20) -> 0.080790197 | I20: =COUNTIFS('Policy Calculations'!$K$30:$K$279,$A20,'Policy Calculations'!$AR$30:$AR$279,"Loss-making") -> 23 | J20: =IF(B20=0,"",I20/B20) -> 0.44230769 | K20: =IF('Portfolio Totals'!$B$13=0,"",G20/'Portfolio Totals'!$B$13) -> 0.32886336 | L20: =IF(B20=0,"No policies",IF(G20<0,"Loss-making segment",IF(H20<Assumptions!$C$16-0.00001,"Below target","At or above target"))) -> At or above target
A21: Bancassurance | B21: =COUNTIFS('Policy Calculations'!$K$30:$K$279,$A21,'Policy Calculations'!$T$30:$T$279,1) -> 65 | C21: =SUMIFS('Policy Calculations'!$M$30:$M$279,'Policy Calculations'!$K$30:$K$279,$A21,'Policy Calculations'!$T$30:$T$279,1) -> 187546.49 | D21: =SUMIFS('Policy Calculations'!$AF$30:$AF$279,'Policy Calculations'!$K$30:$K$279,$A21,'Policy Calculations'!$T$30:$T$279,1) -> 180931.69 | E21: =IF(D21=0,"",C21/D21) -> 1.0365596 | F21: =SUMIFS('Policy Calculations'!$AH$30:$AH$279,'Policy Calculations'!$K$30:$K$279,$A21,'Policy Calculations'!$T$30:$T$279,1) -> 1356203.6 | G21: =SUMIFS('Policy Calculations'!$AI$30:$AI$279,'Policy Calculations'!$K$30:$K$279,$A21,'Policy Calculations'!$T$30:$T$279,1) -> 149908.35 | H21: =IF(F21=0,"",G21/F21) -> 0.11053529 | I21: =COUNTIFS('Policy Calculations'!$K$30:$K$279,$A21,'Policy Calculations'!$AR$30:$AR$279,"Loss-making") -> 22 | J21: =IF(B21=0,"",I21/B21) -> 0.33846154 | K21: =IF('Portfolio Totals'!$B$13=0,"",G21/'Portfolio Totals'!$B$13) -> 0.58496884 | L21: =IF(B21=0,"No policies",IF(G21<0,"Loss-making segment",IF(H21<Assumptions!$C$16-0.00001,"Below target","At or above target"))) -> At or above target
A22: Total | B22: =SUM(B19:B21) -> 169 | C22: =SUM(C19:C21) -> 429880.9 | D22: =SUM(D19:D21) -> 432358.1 | E22: =IF(D22=0,"",C22/D22) -> 0.9942705 | F22: =SUM(F19:F21) -> 3203820.8 | G22: =SUM(G19:G21) -> 256267.25 | H22: =IF(F22=0,"",G22/F22) -> 0.07998801 | I22: =SUM(I19:I21) -> 65 | J22: =IF(B22=0,"",I22/B22) -> 0.38461538 | K22: =G22-'Portfolio Totals'!$B$13 -> 0 | L22: =IF(ABS(K22)<0.01,"Reconciles to portfolio","CHECK") -> Reconciles to portfolio
A24: By entry-age band
A25: Entry-age band | B25: Policies | C25: Charged prem. | D25: Technical prem. | E25: Adequacy | F25: PV premiums | G25: PVFP | H25: NBM | I25: Loss-making | J25: % loss-making | K25: Share of PVFP | L25: Assessment
A26: 20-29 | B26: =COUNTIFS('Policy Calculations'!$AP$30:$AP$279,$A26,'Policy Calculations'!$T$30:$T$279,1) -> 34 | C26: =SUMIFS('Policy Calculations'!$M$30:$M$279,'Policy Calculations'!$AP$30:$AP$279,$A26,'Policy Calculations'!$T$30:$T$279,1) -> 47484.16 | D26: =SUMIFS('Policy Calculations'!$AF$30:$AF$279,'Policy Calculations'!$AP$30:$AP$279,$A26,'Policy Calculations'!$T$30:$T$279,1) -> 38941.752 | E26: =IF(D26=0,"",C26/D26) -> 1.2193637 | F26: =SUMIFS('Policy Calculations'!$AH$30:$AH$279,'Policy Calculations'!$AP$30:$AP$279,$A26,'Policy Calculations'!$T$30:$T$279,1) -> 372230.06 | G26: =SUMIFS('Policy Calculations'!$AI$30:$AI$279,'Policy Calculations'!$AP$30:$AP$279,$A26,'Policy Calculations'!$T$30:$T$279,1) -> 88002.983 | H26: =IF(F26=0,"",G26/F26) -> 0.23642095 | I26: =COUNTIFS('Policy Calculations'!$AP$30:$AP$279,$A26,'Policy Calculations'!$AR$30:$AR$279,"Loss-making") -> 5 | J26: =IF(B26=0,"",I26/B26) -> 0.14705882 | K26: =IF('Portfolio Totals'!$B$13=0,"",G26/'Portfolio Totals'!$B$13) -> 0.34340316 | L26: =IF(B26=0,"No policies",IF(G26<0,"Loss-making segment",IF(H26<Assumptions!$C$16-0.00001,"Below target","At or above target"))) -> At or above target
A27: 30-39 | B27: =COUNTIFS('Policy Calculations'!$AP$30:$AP$279,$A27,'Policy Calculations'!$T$30:$T$279,1) -> 46 | C27: =SUMIFS('Policy Calculations'!$M$30:$M$279,'Policy Calculations'!$AP$30:$AP$279,$A27,'Policy Calculations'!$T$30:$T$279,1) -> 77395.17 | D27: =SUMIFS('Policy Calculations'!$AF$30:$AF$279,'Policy Calculations'!$AP$30:$AP$279,$A27,'Policy Calculations'!$T$30:$T$279,1) -> 74741.957 | E27: =IF(D27=0,"",C27/D27) -> 1.0354983 | F27: =SUMIFS('Policy Calculations'!$AH$30:$AH$279,'Policy Calculations'!$AP$30:$AP$279,$A27,'Policy Calculations'!$T$30:$T$279,1) -> 618458.75 | G27: =SUMIFS('Policy Calculations'!$AI$30:$AI$279,'Policy Calculations'!$AP$30:$AP$279,$A27,'Policy Calculations'!$T$30:$T$279,1) -> 73936.805 | H27: =IF(F27=0,"",G27/F27) -> 0.1195501 | I27: =COUNTIFS('Policy Calculations'!$AP$30:$AP$279,$A27,'Policy Calculations'!$AR$30:$AR$279,"Loss-making") -> 9 | J27: =IF(B27=0,"",I27/B27) -> 0.19565217 | K27: =IF('Portfolio Totals'!$B$13=0,"",G27/'Portfolio Totals'!$B$13) -> 0.28851446 | L27: =IF(B27=0,"No policies",IF(G27<0,"Loss-making segment",IF(H27<Assumptions!$C$16-0.00001,"Below target","At or above target"))) -> At or above target
A28: 40-49 | B28: =COUNTIFS('Policy Calculations'!$AP$30:$AP$279,$A28,'Policy Calculations'!$T$30:$T$279,1) -> 41 | C28: =SUMIFS('Policy Calculations'!$M$30:$M$279,'Policy Calculations'!$AP$30:$AP$279,$A28,'Policy Calculations'!$T$30:$T$279,1) -> 94532.21 | D28: =SUMIFS('Policy Calculations'!$AF$30:$AF$279,'Policy Calculations'!$AP$30:$AP$279,$A28,'Policy Calculations'!$T$30:$T$279,1) -> 97935.199 | E28: =IF(D28=0,"",C28/D28) -> 0.96525265 | F28: =SUMIFS('Policy Calculations'!$AH$30:$AH$279,'Policy Calculations'!$AP$30:$AP$279,$A28,'Policy Calculations'!$T$30:$T$279,1) -> 717786.45 | G28: =SUMIFS('Policy Calculations'!$AI$30:$AI$279,'Policy Calculations'!$AP$30:$AP$279,$A28,'Policy Calculations'!$T$30:$T$279,1) -> 38243.883 | H28: =IF(F28=0,"",G28/F28) -> 0.053280309 | I28: =COUNTIFS('Policy Calculations'!$AP$30:$AP$279,$A28,'Policy Calculations'!$AR$30:$AR$279,"Loss-making") -> 17 | J28: =IF(B28=0,"",I28/B28) -> 0.41463415 | K28: =IF('Portfolio Totals'!$B$13=0,"",G28/'Portfolio Totals'!$B$13) -> 0.14923438 | L28: =IF(B28=0,"No policies",IF(G28<0,"Loss-making segment",IF(H28<Assumptions!$C$16-0.00001,"Below target","At or above target"))) -> Below target
